<mujoco model="simple_joint">
    <compiler angle="degree"/>
    <option timestep="0.01"/>

    <worldbody>
        <!-- 固定基座 -->
        <body name="base" pos="0 0 0">
            <geom type="box" size="0.7 0.7 0.2" rgba="0.2 0.2 0.2 1"/>
            
            <!-- 旋转关节 S -->
            <body name="link_s" pos="-0.5 0.5 0.2">
                <joint name="hinge_s" type="hinge" axis="0 0 1" pos="0 0 0"/>
                <geom type="capsule" fromto="0 0 0  0 0 0.2" size="0.05" rgba="0.53 0.81 0.92 1"/>
                <body name="indicator_s" pos="0 0.1 0.2">
                    <geom type="box" size="0.02 0.1 0.005" rgba="0 0 1 1"/>
                </body>
            </body>

            <!-- 旋转关节 0 -->
            <body name="link_0" pos="0 0.5 0.2">
                <joint name="hinge_0" type="hinge" axis="0 0 1" pos="0 0 0"/>
                <geom type="capsule" fromto="0 0 0  0 0 0.2" size="0.05" rgba="0.53 0.81 0.92 1"/>
                <body name="indicator_0" pos="0 0.1 0.2">
                    <geom type="box" size="0.02 0.1 0.005" rgba="0 0 1 1"/>
                </body>
            </body>

            <!-- 旋转关节 1 -->
            <body name="link_1" pos="0.5 0.5 0.2">
                <joint name="hinge_1" type="hinge" axis="0 0 1" pos="0 0 0"/>
                <geom type="capsule" fromto="0 0 0  0 0 0.2" size="0.05" rgba="0.53 0.81 0.92 1"/>
                <body name="indicator_1" pos="0 0.1 0.2">
                    <geom type="box" size="0.02 0.1 0.005" rgba="0 0 1 1"/>
                </body>
            </body>

            <!-- 旋转关节 2 -->
            <body name="link_2" pos="-0.5 0 0.2">
                <joint name="hinge_2" type="hinge" axis="0 0 1" pos="0 0 0"/>
                <geom type="capsule" fromto="0 0 0  0 0 0.2" size="0.05" rgba="0.53 0.81 0.92 1"/>
                <body name="indicator_2" pos="0 0.1 0.2">
                    <geom type="box" size="0.02 0.1 0.005" rgba="0 0 1 1"/>
                </body>
            </body>

            <!-- 旋转关节 3 -->
            <body name="link_3" pos="0 0 0.2">
                <joint name="hinge_3" type="hinge" axis="0 0 1" pos="0 0 0"/>
                <geom type="capsule" fromto="0 0 0  0 0 0.2" size="0.05" rgba="0.53 0.81 0.92 1"/>
                <body name="indicator_3" pos="0 0.1 0.2">
                    <geom type="box" size="0.02 0.1 0.005" rgba="0 0 1 1"/>
                </body>
            </body>

            <!-- 旋转关节 4 -->
            <body name="link_4" pos="0.5 0 0.2">
                <joint name="hinge_4" type="hinge" axis="0 0 1" pos="0 0 0"/>
                <geom type="capsule" fromto="0 0 0  0 0 0.2" size="0.05" rgba="0.53 0.81 0.92 1"/>
                <body name="indicator_4" pos="0 0.1 0.2">
                    <geom type="box" size="0.02 0.1 0.005" rgba="0 0 1 1"/>
                </body>
            </body>

            <!-- 旋转关节 5 -->
            <body name="link_5" pos="-0.5 -0.5 0.2">
                <joint name="hinge_5" type="hinge" axis="0 0 1" pos="0 0 0"/>
                <geom type="capsule" fromto="0 0 0  0 0 0.2" size="0.05" rgba="0.53 0.81 0.92 1"/>
                <body name="indicator_5" pos="0 0.1 0.2">
                    <geom type="box" size="0.02 0.1 0.005" rgba="0 0 1 1"/>
                </body>
            </body>

            <!-- 旋转关节 6 -->
            <body name="link_6" pos="0 -0.5 0.2">
                <joint name="hinge_6" type="hinge" axis="0 0 1" pos="0 0 0"/>
                <geom type="capsule" fromto="0 0 0  0 0 0.2" size="0.05" rgba="0.53 0.81 0.92 1"/>
                <body name="indicator_6" pos="0 0.1 0.2">
                    <geom type="box" size="0.02 0.1 0.005" rgba="0 0 1 1"/>
                </body>
            </body>

            <!-- 旋转关节 7 -->
            <body name="link_7" pos="0.5 -0.5 0.2">
                <joint name="hinge_7" type="hinge" axis="0 0 1" pos="0 0 0"/>
                <geom type="capsule" fromto="0 0 0  0 0 0.2" size="0.05" rgba="0.53 0.81 0.92 1"/>
                <body name="indicator_7" pos="0 0.1 0.2">
                    <geom type="box" size="0.02 0.1 0.005" rgba="0 0 1 1"/>
                </body>
            </body>

        </body>
    </worldbody>
</mujoco>
