<mujoco model="simple_joint_stable">
    <asset>
        <texture name="grid" type="2d" builtin="checker" rgb1=".1 .2 .3"
                 rgb2=".2 .3 .4" width="300" height="300" mark="edge" markrgb=".2 .3 .4"/>
        <material name="grid" texture="grid" texrepeat="2 2" texuniform="true" reflectance=".2"/>
    </asset>

    <!-- 使用较小的 timestep 和 RK4 积分器以提高数值稳定性 -->
    <compiler angle="degree"/>
    <option timestep="0.002" integrator="RK4"/>

    <worldbody>
        <light pos="0 0 1" mode="trackcom"/>
        <geom name="ground" type="plane" size="5 5 10" material="grid" 
              friction="1 0.05 0.0001"/>
        <camera name="y" pos="-.1 -.6 .3" xyaxes="1 0 0 0 1 2"/>
        
        <!-- 固定基座 -->
        <body name="base" pos="0 0 0">
            <body name="link">
                <joint name="hinge" type="hinge" axis="0 0 1" damping="2.0" frictionloss="10.0"/>
                <geom name="hinge" type="capsule" fromto="0 0 0 0 0 0.2" size="0.05" rgba="0.53 0.81 0.92 1"/>
                
                <body name="indicator" pos="0 0.5 0.2">
                    <geom name="indicator_geom" type="box" size="0.02 0.5 0.05" rgba="0 0 1 1" 
                          mass="10" solref="0.02 1.0" solimp="0.9 0.95" friction="0.5" />
                    <site name="indicator_site" pos="0 0 0" size="0.01" />
                </body>
            </body>
        </body>

        <!-- 修改后的物块：在自由关节上增加阻尼和臂力参数 -->
        <body name="block" pos="-0.5 0.5 0.2">
            <joint type="free" damping="0.1" armature="0.1"/>
            <geom name="box" type="box" size="0.2 0.2 0.2" rgba="1 0 0 1" 
                  friction="0.2" mass="10" solref="0.02 1.0" solimp="0.9 0.95" />
        </body>

    </worldbody>

    <actuator>
        <motor joint="hinge" ctrlrange="-500 500"/>
    </actuator>

    <sensor>
        <!-- 使用 site 测量力 -->
        <force name="indicator_force" site="indicator_site"/>
        <touch name="touch" site="indicator_site" />
    </sensor>

</mujoco>
